2025-07-03 08:06:53,801 INFO    MainThread:4194103 [wandb_setup.py:_flush():77] Current SDK version is 0.17.9
2025-07-03 08:06:53,801 INFO    MainThread:4194103 [wandb_setup.py:_flush():77] Configure stats pid to 4194103
2025-07-03 08:06:53,801 INFO    MainThread:4194103 [wandb_setup.py:_flush():77] Loading settings from /home/liqifeng/.config/wandb/settings
2025-07-03 08:06:53,801 INFO    MainThread:4194103 [wandb_setup.py:_flush():77] Loading settings from /data1/lqf/behavior_simulation/wandb/settings
2025-07-03 08:06:53,801 INFO    MainThread:4194103 [wandb_setup.py:_flush():77] Loading settings from environment variables: {}
2025-07-03 08:06:53,801 INFO    MainThread:4194103 [wandb_setup.py:_flush():77] Applying setup settings: {'_disable_service': False}
2025-07-03 08:06:53,801 INFO    MainThread:4194103 [wandb_setup.py:_flush():77] Inferring run settings from compute environment: {'program_relpath': 'test.py', 'program_abspath': '/data1/lqf/behavior_simulation/test.py', 'program': '/data1/lqf/behavior_simulation/test.py'}
2025-07-03 08:06:53,801 INFO    MainThread:4194103 [wandb_setup.py:_flush():77] Applying login settings: {}
2025-07-03 08:06:53,802 INFO    MainThread:4194103 [wandb_init.py:_log_setup():524] Logging user logs to /data1/lqf/behavior_simulation/wandb/run-20250703_080653-ddcu9qsm/logs/debug.log
2025-07-03 08:06:53,802 INFO    MainThread:4194103 [wandb_init.py:_log_setup():525] Logging internal logs to /data1/lqf/behavior_simulation/wandb/run-20250703_080653-ddcu9qsm/logs/debug-internal.log
2025-07-03 08:06:53,802 INFO    MainThread:4194103 [wandb_init.py:init():608] calling init triggers
2025-07-03 08:06:53,802 INFO    MainThread:4194103 [wandb_init.py:init():615] wandb.init called with sweep_config: {}
config: {'learning_rate': 0.02, 'architecture': 'CNN', 'dataset': 'CIFAR-100', 'epochs': 10}
2025-07-03 08:06:53,802 INFO    MainThread:4194103 [wandb_init.py:init():658] starting backend
2025-07-03 08:06:53,802 INFO    MainThread:4194103 [wandb_init.py:init():662] setting up manager
2025-07-03 08:06:53,804 INFO    MainThread:4194103 [backend.py:_multiprocessing_setup():105] multiprocessing start_methods=fork,spawn,forkserver, using: spawn
2025-07-03 08:06:53,804 INFO    MainThread:4194103 [wandb_init.py:init():670] backend started and connected
2025-07-03 08:06:53,808 INFO    MainThread:4194103 [wandb_init.py:init():768] updated telemetry
2025-07-03 08:06:53,809 INFO    MainThread:4194103 [wandb_init.py:init():801] communicating run to backend with 90.0 second timeout
2025-07-03 08:07:52,100 INFO    Thread-1 (wrapped_target):4194103 [retry.py:__call__():172] Retry attempt failed:
Traceback (most recent call last):
  File "/data1/lqf/conda_envs/catk/lib/python3.11/site-packages/urllib3/connection.py", line 198, in _new_conn
    sock = connection.create_connection(
           ^^^^^^^^^^^^^^^^^^^^^^^^^^^^^
  File "/data1/lqf/conda_envs/catk/lib/python3.11/site-packages/urllib3/util/connection.py", line 85, in create_connection
    raise err
  File "/data1/lqf/conda_envs/catk/lib/python3.11/site-packages/urllib3/util/connection.py", line 73, in create_connection
    sock.connect(sa)
TimeoutError: timed out

The above exception was the direct cause of the following exception:

Traceback (most recent call last):
  File "/data1/lqf/conda_envs/catk/lib/python3.11/site-packages/urllib3/connectionpool.py", line 787, in urlopen
    response = self._make_request(
               ^^^^^^^^^^^^^^^^^^^
  File "/data1/lqf/conda_envs/catk/lib/python3.11/site-packages/urllib3/connectionpool.py", line 488, in _make_request
    raise new_e
  File "/data1/lqf/conda_envs/catk/lib/python3.11/site-packages/urllib3/connectionpool.py", line 464, in _make_request
    self._validate_conn(conn)
  File "/data1/lqf/conda_envs/catk/lib/python3.11/site-packages/urllib3/connectionpool.py", line 1093, in _validate_conn
    conn.connect()
  File "/data1/lqf/conda_envs/catk/lib/python3.11/site-packages/urllib3/connection.py", line 753, in connect
    self.sock = sock = self._new_conn()
                       ^^^^^^^^^^^^^^^^
  File "/data1/lqf/conda_envs/catk/lib/python3.11/site-packages/urllib3/connection.py", line 207, in _new_conn
    raise ConnectTimeoutError(
urllib3.exceptions.ConnectTimeoutError: (<urllib3.connection.HTTPSConnection object at 0x7f755be410d0>, 'Connection to api.wandb.ai timed out. (connect timeout=20)')

The above exception was the direct cause of the following exception:

Traceback (most recent call last):
  File "/data1/lqf/conda_envs/catk/lib/python3.11/site-packages/requests/adapters.py", line 667, in send
    resp = conn.urlopen(
           ^^^^^^^^^^^^^
  File "/data1/lqf/conda_envs/catk/lib/python3.11/site-packages/urllib3/connectionpool.py", line 841, in urlopen
    retries = retries.increment(
              ^^^^^^^^^^^^^^^^^^
  File "/data1/lqf/conda_envs/catk/lib/python3.11/site-packages/urllib3/util/retry.py", line 519, in increment
    raise MaxRetryError(_pool, url, reason) from reason  # type: ignore[arg-type]
    ^^^^^^^^^^^^^^^^^^^^^^^^^^^^^^^^^^^^^^^^^^^^^^^^^^^
urllib3.exceptions.MaxRetryError: HTTPSConnectionPool(host='api.wandb.ai', port=443): Max retries exceeded with url: /graphql (Caused by ConnectTimeoutError(<urllib3.connection.HTTPSConnection object at 0x7f755be410d0>, 'Connection to api.wandb.ai timed out. (connect timeout=20)'))

During handling of the above exception, another exception occurred:

Traceback (most recent call last):
  File "/data1/lqf/conda_envs/catk/lib/python3.11/site-packages/wandb/sdk/lib/retry.py", line 131, in __call__
    result = self._call_fn(*args, **kwargs)
             ^^^^^^^^^^^^^^^^^^^^^^^^^^^^^^
  File "/data1/lqf/conda_envs/catk/lib/python3.11/site-packages/wandb/sdk/internal/internal_api.py", line 345, in execute
    return self.client.execute(*args, **kwargs)  # type: ignore
           ^^^^^^^^^^^^^^^^^^^^^^^^^^^^^^^^^^^^
  File "/data1/lqf/conda_envs/catk/lib/python3.11/site-packages/wandb/vendor/gql-0.2.0/wandb_gql/client.py", line 52, in execute
    result = self._get_result(document, *args, **kwargs)
             ^^^^^^^^^^^^^^^^^^^^^^^^^^^^^^^^^^^^^^^^^^^
  File "/data1/lqf/conda_envs/catk/lib/python3.11/site-packages/wandb/vendor/gql-0.2.0/wandb_gql/client.py", line 60, in _get_result
    return self.transport.execute(document, *args, **kwargs)
           ^^^^^^^^^^^^^^^^^^^^^^^^^^^^^^^^^^^^^^^^^^^^^^^^^
  File "/data1/lqf/conda_envs/catk/lib/python3.11/site-packages/wandb/sdk/lib/gql_request.py", line 58, in execute
    request = self.session.post(self.url, **post_args)
              ^^^^^^^^^^^^^^^^^^^^^^^^^^^^^^^^^^^^^^^^
  File "/data1/lqf/conda_envs/catk/lib/python3.11/site-packages/requests/sessions.py", line 637, in post
    return self.request("POST", url, data=data, json=json, **kwargs)
           ^^^^^^^^^^^^^^^^^^^^^^^^^^^^^^^^^^^^^^^^^^^^^^^^^^^^^^^^^
  File "/data1/lqf/conda_envs/catk/lib/python3.11/site-packages/requests/sessions.py", line 589, in request
    resp = self.send(prep, **send_kwargs)
           ^^^^^^^^^^^^^^^^^^^^^^^^^^^^^^
  File "/data1/lqf/conda_envs/catk/lib/python3.11/site-packages/requests/sessions.py", line 703, in send
    r = adapter.send(request, **kwargs)
        ^^^^^^^^^^^^^^^^^^^^^^^^^^^^^^^
  File "/data1/lqf/conda_envs/catk/lib/python3.11/site-packages/requests/adapters.py", line 688, in send
    raise ConnectTimeout(e, request=request)
requests.exceptions.ConnectTimeout: HTTPSConnectionPool(host='api.wandb.ai', port=443): Max retries exceeded with url: /graphql (Caused by ConnectTimeoutError(<urllib3.connection.HTTPSConnection object at 0x7f755be410d0>, 'Connection to api.wandb.ai timed out. (connect timeout=20)'))
